Workbook
Name Acq_date: LBO!$I$28
Name Acq_EBITDA: LBO!$M$28
Name Acq_multiple: LBO!$I$25
Name Currency: LBO!$I$10
Name Debt_EBITDA: LBO!$I$38
Name EBITDA_basis: LBO!$H$26
Name Existing_net_debt: LBO!$I$81
Name Exit_multiple: LBO!$I$27
Name First_FYE: LBO!$I$5
Name FYE_post_acq: LBO!$I$11
Name Hardcode_AC186: LBO!$AC$186
Name Hardcode_S118: LBO!$S$118
Name Hardcode_source_M103: LBO!$M$103
Name Hardcode_X191: LBO!$X$191
Name Holding_period: LBO!$I$30
Name MA_fees: LBO!$I$32
Name Min_cash: LBO!$H$50
Name Min_equity: LBO!$I$40
Name Pref_interest: LBO!$I$66
Name Project_name: LBO!$I$8
Name RCF_quantum: LBO!$H$56
Name RCF_switch: LBO!$I$56
Name Scenario_1: LBO!$I$17
Name Scenario_2: LBO!$I$18
Name Scenario_3: LBO!$I$19
Name Scenario_5: LBO!$I$21
Name Scenario_provider: LBO!$I$9
Name Scenario_selected: LBO!$I$20
Name Step_multiple: LBO!$J$25
Name stub: LBO!$I$29
Name Tax_rate: LBO!$I$12
Name TLA_split: LBO!$H$54

Sheet Client_FS
J3: Actual | M3: Forecast
J4: 45291 | K4: 45657 | L4: 46022 | M4: 46387 | N4: 46752 | O4: 47118 | P4: 47483 | Q4: 47848 | R4: 48213 | S4: 48579
J5: 2023 | K5: 2024 | L5: 2025 | M5: 2026 | N5: 2027 | O5: 2028 | P5: 2029 | Q5: 2030 | R5: 2031 | S5: 2032
E6: Revenue Core 1 | J6: 29584299 | K6: 31955914 | L6: 34350355 | M6: 36061074 | N6: 37210596 | O6: 38321300 | P6: 39464976 | Q6: 40643298 | R6: 41856963 | S6: 43035387
E7: Revenue Expansion 1
E8: Revenue Core 2 | J8: 16248891 | K8: 18856416 | L8: 20147809 | M8: 20983779 | N8: 21823130 | O8: 22696055 | P8: 24057818 | Q8: 24972015 | R8: 25920952 | S8: 26905948
E9: Revenue Expansion 2
E10: M&A Revenue
D11: Total revenue | J11: =SUM(J6:J9) -> 45833190 | K11: =SUM(K6:K9) -> 50812330 | L11: =SUM(L6:L9) -> 54498164 | M11: =SUM(M6:M9) -> 57044852 | N11: =SUM(N6:N9) -> 59033726 | O11: =SUM(O6:O9) -> 61017355 | P11: =SUM(P6:P9) -> 63522795 | Q11: =SUM(Q6:Q9) -> 65615314 | ... S11: =SUM(S6:S9) -> 69941336
E13: EBITDA Core 1 | J13: 4471641.1 | K13: 5135402.4 | L13: 5611266.5 | M13: 5658934.4 | N13: 5743322.2 | O13: 5898715.7 | P13: 6108420.2 | Q13: 6328801.9 | R13: 6536827.6 | S13: 6733081.4
E14: EBITDA Expansion 1
E15: EBITDA Core 2 | J15: 2079194.9 | K15: 4564881.8 | L15: 4958351 | M15: 5383844.8 | N15: 5658095.4 | O15: 6073060.1 | P15: 6403720.5 | Q15: 6808512.6 | R15: 7227678.7 | S15: 7661568.1
E16: EBITDA Expansion 2
E17: M&A EBITDA | J17: 0 | K17: 0 | L17: 0 | M17: 250000 | N17: 1000000 | O17: 1030000 | P17: 1060900 | Q17: 1092727 | R17: 1125508.8 | S17: 1159274.1
E18: Staff efficiencies | J18: 0 | K18: 0 | L18: 0 | M18: -16077.25 | N18: 635551.5 | O18: 729310.04 | P18: 751189.34 | Q18: 773725.02 | R18: 796936.77 | S18: 820844.88
E19: Family costs | J19: 0 | K19: 0 | L19: 0 | M19: 201783.28 | N19: 484279.88 | O19: 498808.28 | P19: 513772.52 | Q19: 529185.7 | R19: 545061.27 | S19: 561413.11
D20: EBITDA | J20: =SUM(J13:J19) -> 6550836 | K20: =SUM(K13:K19) -> 9700284.2 | L20: =SUM(L13:L19) -> 10569617 | M20: =SUM(M13:M19) -> 11478485 | N20: =SUM(N13:N19) -> 13521249 | O20: =SUM(O13:O19) -> 14229894 | P20: =SUM(P13:P19) -> 14838003 | Q20: =SUM(Q13:Q19) -> 15532952 | ... S20: =SUM(S13:S19) -> 16936182
F21: M&A EBITDA | O21: =+O17/N17-1 -> 0.03 | P21: =+P17/O17-1 -> 0.03 | Q21: =+Q17/P17-1 -> 0.03 | R21: 0.03 | S21: 0.03
F22: Staff efficiencies | O22: =+O18/N18-1 -> 0.14752312 | P22: =+P18/O18-1 -> 0.03 | Q22: =+Q18/P18-1 -> 0.03 | R22: 0.03 | S22: 0.03
F23: Family costs | O23: =+O19/N19-1 -> 0.03 | P23: =+P19/O19-1 -> 0.03 | Q23: =+Q19/P19-1 -> 0.03 | R23: 0.03 | S23: 0.03
E25: Depreciation Core 1 | J25: -1256947.9 | K25: -875356.88 | L25: -902095.69 | M25: -833767.38 | N25: -960879.87 | O25: -1033607.7 | P25: -1116949.4 | Q25: -1171002.2 | R25: -1160547.6 | S25: -1160353
E26: Depreciation Expansion 1
E27: Depreciation Core 2 | J27: -1413993.9 | K27: -1672066.6 | L27: -2059740.6 | M27: -2253571.6 | N27: -2312718.5 | O27: -2325871 | P27: -2415434 | Q27: -2491444.4 | R27: -2491444.4 | S27: -1406816.4
E28: Depreciation Expansion 2
E29: M&A Depreciation
D30: Depreciation | J30: =SUM(J25:J28) -> -2670941.8 | K30: =SUM(K25:K28) -> -2547423.4 | L30: =SUM(L25:L28) -> -2961836.3 | M30: =SUM(M25:M28) -> -3087339 | N30: =SUM(N25:N28) -> -3273598.4 | O30: =SUM(O25:O28) -> -3359478.7 | P30: =SUM(P25:P28) -> -3532383.4 | Q30: =SUM(Q25:Q28) -> -3662446.6 | ... S30: =SUM(S25:S28) -> -2567169.4
E32: Change in NWC Core 1 | K32: -517791.25 | L32: -2015154.7 | M32: 2789219 | N32: 975000 | O32: -607358.39 | P32: -1878810.3 | Q32: -3039700 | R32: -3266581.7 | S32: -3480019.6
E33: Change in NWC Core 2 | K33: -261104.28 | L33: 161655.98 | M33: 305096.74 | N33: 266809.07 | O33: 350756.22 | P33: 373408.03 | Q33: 391810.17 | R33: 414201.92 | S33: 437882.74
E34: Change in NWC Expansion
E35: Change in NWC M&A
D36: Change in NWC | J36: =SUM(J32:J35) -> 0 | K36: =SUM(K32:K35) -> -778895.53 | L36: =SUM(L32:L35) -> -1853498.7 | M36: =SUM(M32:M35) -> 3094315.8 | N36: =SUM(N32:N35) -> 1241809.1 | O36: =SUM(O32:O35) -> -256602.18 | P36: =SUM(P32:P35) -> -1505402.3 | Q36: =SUM(Q32:Q35) -> -2647889.8 | ... S36: =SUM(S32:S35) -> -3042136.8
E38: Maintenance Capex Core 1 | J38: -1613813.9 | K38: -907966.59 | L38: 195515.28 | M38: -1014500 | N38: -1000000 | O38: -1000000 | P38: -1000000 | Q38: -1000000 | R38: -1000000 | S38: -1000000
E39: Growth Capex Expansion 1
E40: Maintenance Capex Core 2 | J40: -3899585.1 | K40: -2004497.9 | L40: -3409752.9 | M40: -450000 | N40: -1000000 | O40: -1000000 | P40: -1000000 | Q40: -1000000 | R40: -1000000 | S40: -1000000
E41: Growth Capex Expansion 2
E42: M&A Capex
D43: Capex | J43: =SUM(J38:J41) -> -5513399 | K43: =SUM(K38:K41) -> -2912464.5 | L43: =SUM(L38:L41) -> -3214237.6 | M43: =SUM(M38:M41) -> -1464500 | N43: =SUM(N38:N41) -> -2000000 | O43: =SUM(O38:O41) -> -2000000 | P43: =SUM(P38:P41) -> -2000000 | Q43: =SUM(Q38:Q41) -> -2000000 | ... S43: =SUM(S38:S41) -> -2000000

Sheet OpModel_Link
Q1: =J3 -> 46387 | R1: =L3 -> 47118 | S1: =P3 -> 48579
B2: ="SCENARIO: "&LBO!I20 -> SCENARIO: 1 | H2: =LBO!I6 -> Actual | I2: =LBO!J6 -> Actual | J2: =LBO!K6 -> Outlook | K2: =LBO!L6 -> Forecast | L2: =LBO!M6 -> Forecast | M2: =LBO!N6 -> Forecast | N2: =LBO!O6 -> Forecast | O2: =LBO!P6 -> Forecast | P2: =LBO!Q6 -> Forecast | Q2: =P2 -> Forecast | R2: CAGR | U2: Comment
B3: Year end | G3: switch | H3: =LBO!I5 -> 45657 | I3: =LBO!J5 -> 46022 | J3: =LBO!K5 -> 46387 | K3: =LBO!L5 -> 46752 | L3: =LBO!M5 -> 47118 | M3: =LBO!N5 -> 47483 | N3: =LBO!O5 -> 47848 | O3: =LBO!P5 -> 48213 | P3: =LBO!Q5 -> 48579 | Q3: =EDATE(P3,12) -> 48944 | R3: =+TEXT(Q1,"'yy")&" - "&TEXT(R1,"'yy") -> '26 - '28 | S3: =+TEXT(R1,"'yy")&" - "&TEXT(S1,"'yy") -> '28 - '32
B5: =+Client_FS!E6 -> Revenue Core 1 | H5: =(SUMIFS(Client_FS!$J6:$S6,Client_FS!$J$4:$S$4,H$3))/1000000 -> 31.955914 | I5: =(SUMIFS(Client_FS!$J6:$S6,Client_FS!$J$4:$S$4,I$3)+SUMIFS(Client_FS!$J8:$S8,Client_FS!$J$4:$S$4,I$3))/1000000 -> 54.498164 | J5: =(SUMIFS(Client_FS!$J6:$S6,Client_FS!$J$4:$S$4,J$3)+SUMIFS(Client_FS!$J8:$S8,Client_FS!$J$4:$S$4,J$3))/1000000 -> 57.044852 | K5: =(SUMIFS(Client_FS!$J6:$S6,Client_FS!$J$4:$S$4,K$3)+SUMIFS(Client_FS!$J8:$S8,Client_FS!$J$4:$S$4,K$3))/1000000 -> 59.033726 | L5: =(SUMIFS(Client_FS!$J6:$S6,Client_FS!$J$4:$S$4,L$3)+SUMIFS(Client_FS!$J8:$S8,Client_FS!$J$4:$S$4,L$3))/1000000 -> 61.017355 | M5: =(SUMIFS(Client_FS!$J6:$S6,Client_FS!$J$4:$S$4,M$3)+SUMIFS(Client_FS!$J8:$S8,Client_FS!$J$4:$S$4,M$3))/1000000 -> 63.522795 | N5: =(SUMIFS(Client_FS!$J6:$S6,Client_FS!$J$4:$S$4,N$3)+SUMIFS(Client_FS!$J8:$S8,Client_FS!$J$4:$S$4,N$3))/1000000 -> 65.615314 | O5: =(SUMIFS(Client_FS!$J6:$S6,Client_FS!$J$4:$S$4,O$3)+SUMIFS(Client_FS!$J8:$S8,Client_FS!$J$4:$S$4,O$3))/1000000 -> 67.777915 | P5: =(SUMIFS(Client_FS!$J6:$S6,Client_FS!$J$4:$S$4,P$3)+SUMIFS(Client_FS!$J8:$S8,Client_FS!$J$4:$S$4,P$3))/1000000 -> 69.941336
B6: =+Client_FS!E7 -> Revenue Expansion 1 | G6: =+LBO!I17 -> 0 | H6: =(SUMIFS(Client_FS!$J7:$S7,Client_FS!$J$4:$S$4,H$3))/1000000*$G6 -> 0 | I6: =(SUMIFS(Client_FS!$J7:$S7,Client_FS!$J$4:$S$4,I$3))/1000000*$G6 -> 0 | J6: =(SUMIFS(Client_FS!$J7:$S7,Client_FS!$J$4:$S$4,J$3))/1000000*$G6 -> 0 | K6: =(SUMIFS(Client_FS!$J7:$S7,Client_FS!$J$4:$S$4,K$3))/1000000*$G6 -> 0 | L6: =(SUMIFS(Client_FS!$J7:$S7,Client_FS!$J$4:$S$4,L$3))/1000000*$G6 -> 0 | M6: =(SUMIFS(Client_FS!$J7:$S7,Client_FS!$J$4:$S$4,M$3))/1000000*$G6 -> 0 | N6: =(SUMIFS(Client_FS!$J7:$S7,Client_FS!$J$4:$S$4,N$3))/1000000*$G6 -> 0 | O6: =(SUMIFS(Client_FS!$J7:$S7,Client_FS!$J$4:$S$4,O$3))/1000000*$G6 -> 0 | P6: =(SUMIFS(Client_FS!$J7:$S7,Client_FS!$J$4:$S$4,P$3))/1000000*$G6 -> 0
B7: =+Client_FS!E8 -> Revenue Core 2 | H7: =+SUMIFS(Client_FS!$J8:$S8,Client_FS!$J$4:$S$4,H$3)/1000000 -> 18.856416 | I7: =+SUMIFS(Client_FS!$J8:$S8,Client_FS!$J$4:$S$4,I$3)/1000000 -> 20.147809 | J7: =+SUMIFS(Client_FS!$J8:$S8,Client_FS!$J$4:$S$4,J$3)/1000000 -> 20.983779 | K7: =+SUMIFS(Client_FS!$J8:$S8,Client_FS!$J$4:$S$4,K$3)/1000000 -> 21.82313 | L7: =+SUMIFS(Client_FS!$J8:$S8,Client_FS!$J$4:$S$4,L$3)/1000000 -> 22.696055 | M7: =+SUMIFS(Client_FS!$J8:$S8,Client_FS!$J$4:$S$4,M$3)/1000000 -> 24.057818 | N7: =+SUMIFS(Client_FS!$J8:$S8,Client_FS!$J$4:$S$4,N$3)/1000000 -> 24.972015 | O7: =+SUMIFS(Client_FS!$J8:$S8,Client_FS!$J$4:$S$4,O$3)/1000000 -> 25.920952 | P7: =+SUMIFS(Client_FS!$J8:$S8,Client_FS!$J$4:$S$4,P$3)/1000000 -> 26.905948
B8: =+Client_FS!E9 -> Revenue Expansion 2 | G8: =+LBO!I18 -> 0 | H8: =(SUMIFS(Client_FS!$J9:$S9,Client_FS!$J$4:$S$4,H$3))/1000000*$G8 -> 0 | I8: =(SUMIFS(Client_FS!$J9:$S9,Client_FS!$J$4:$S$4,I$3))/1000000*$G8 -> 0 | J8: =(SUMIFS(Client_FS!$J9:$S9,Client_FS!$J$4:$S$4,J$3))/1000000*$G8 -> 0 | K8: =(SUMIFS(Client_FS!$J9:$S9,Client_FS!$J$4:$S$4,K$3))/1000000*$G8 -> 0 | L8: =(SUMIFS(Client_FS!$J9:$S9,Client_FS!$J$4:$S$4,L$3))/1000000*$G8 -> 0 | M8: =(SUMIFS(Client_FS!$J9:$S9,Client_FS!$J$4:$S$4,M$3))/1000000*$G8 -> 0 | N8: =(SUMIFS(Client_FS!$J9:$S9,Client_FS!$J$4:$S$4,N$3))/1000000*$G8 -> 0 | O8: =(SUMIFS(Client_FS!$J9:$S9,Client_FS!$J$4:$S$4,O$3))/1000000*$G8 -> 0 | P8: =(SUMIFS(Client_FS!$J9:$S9,Client_FS!$J$4:$S$4,P$3))/1000000*$G8 -> 0
B9: =+Client_FS!E10 -> M&A Revenue | G9: =+LBO!I21 -> 0 | H9: =(SUMIFS(Client_FS!$J10:$S10,Client_FS!$J$4:$S$4,H$3))/1000000*$G9 -> 0 | I9: =(SUMIFS(Client_FS!$J10:$S10,Client_FS!$J$4:$S$4,I$3))/1000000*$G9 -> 0 | J9: =(SUMIFS(Client_FS!$J10:$S10,Client_FS!$J$4:$S$4,J$3))/1000000*$G9 -> 0 | K9: =(SUMIFS(Client_FS!$J10:$S10,Client_FS!$J$4:$S$4,K$3))/1000000*$G9 -> 0 | L9: =(SUMIFS(Client_FS!$J10:$S10,Client_FS!$J$4:$S$4,L$3))/1000000*$G9 -> 0 | M9: =(SUMIFS(Client_FS!$J10:$S10,Client_FS!$J$4:$S$4,M$3))/1000000*$G9 -> 0 | N9: =(SUMIFS(Client_FS!$J10:$S10,Client_FS!$J$4:$S$4,N$3))/1000000*$G9 -> 0 | O9: =(SUMIFS(Client_FS!$J10:$S10,Client_FS!$J$4:$S$4,O$3))/1000000*$G9 -> 0 | P9: =(SUMIFS(Client_FS!$J10:$S10,Client_FS!$J$4:$S$4,P$3))/1000000*$G9 -> 0
B10: REVENUE | H10: =SUM(H5:H9) -> 50.81233 | I10: =SUM(I5:I9) -> 74.645973 | J10: =SUM(J5:J9) -> 78.028631 | K10: =SUM(K5:K9) -> 80.856855 | L10: =SUM(L5:L9) -> 83.71341 | M10: =SUM(M5:M9) -> 87.580613 | N10: =SUM(N5:N9) -> 90.587329 | O10: =SUM(O5:O9) -> 93.698867 | P10: =SUM(P5:P9) -> 96.847284 | Q10: =P10*(1+Q11) -> 100.10149
B11: % growth | H11: =IFERROR(H10/G10-1,"") | I11: =IFERROR(I10/H10-1,"") -> 0.46905236 | J11: =IFERROR(J10/I10-1,"") -> 0.045316013 | K11: =IFERROR(K10/J10-1,"") -> 0.036245982 | L11: =IFERROR(L10/K10-1,"") -> 0.035328535 | M11: =IFERROR(M10/L10-1,"") -> 0.046195746 | N11: =IFERROR(N10/M10-1,"") -> 0.034330841 | O11: =IFERROR(O10/N10-1,"") -> 0.034348488 | P11: =IFERROR(P10/O10-1,"") -> 0.033601439 | Q11: =P11 -> 0.033601439
B13: =+Client_FS!E13 -> EBITDA Core 1 | H13: =(SUMIFS(Client_FS!$J13:$S13,Client_FS!$J$4:$S$4,H$3)/1000000) -> 5.1354024 | I13: =(SUMIFS(Client_FS!$J13:$S13,Client_FS!$J$4:$S$4,I$3)/1000000) -> 5.6112665 | J13: =(SUMIFS(Client_FS!$J13:$S13,Client_FS!$J$4:$S$4,J$3)/1000000) -> 5.6589344 | K13: =(SUMIFS(Client_FS!$J13:$S13,Client_FS!$J$4:$S$4,K$3)/1000000) -> 5.7433222 | L13: =(SUMIFS(Client_FS!$J13:$S13,Client_FS!$J$4:$S$4,L$3)/1000000) -> 5.8987157 | M13: =(SUMIFS(Client_FS!$J13:$S13,Client_FS!$J$4:$S$4,M$3)/1000000) -> 6.1084202 | N13: =(SUMIFS(Client_FS!$J13:$S13,Client_FS!$J$4:$S$4,N$3)/1000000) -> 6.3288019 | O13: =(SUMIFS(Client_FS!$J13:$S13,Client_FS!$J$4:$S$4,O$3)/1000000) -> 6.5368276 | P13: =(SUMIFS(Client_FS!$J13:$S13,Client_FS!$J$4:$S$4,P$3)/1000000) -> 6.7330814
B14: =+Client_FS!E15 -> EBITDA Core 2 | H14: =+SUMIFS(Client_FS!$J15:$S15,Client_FS!$J$4:$S$4,H$3)/1000000 -> 4.5648818 | I14: =+SUMIFS(Client_FS!$J15:$S15,Client_FS!$J$4:$S$4,I$3)/1000000 -> 4.958351 | J14: =+SUMIFS(Client_FS!$J15:$S15,Client_FS!$J$4:$S$4,J$3)/1000000 -> 5.3838448 | K14: =+SUMIFS(Client_FS!$J15:$S15,Client_FS!$J$4:$S$4,K$3)/1000000 -> 5.6580954 | L14: =+SUMIFS(Client_FS!$J15:$S15,Client_FS!$J$4:$S$4,L$3)/1000000 -> 6.0730601 | M14: =+SUMIFS(Client_FS!$J15:$S15,Client_FS!$J$4:$S$4,M$3)/1000000 -> 6.4037205 | N14: =+SUMIFS(Client_FS!$J15:$S15,Client_FS!$J$4:$S$4,N$3)/1000000 -> 6.8085126 | O14: =+SUMIFS(Client_FS!$J15:$S15,Client_FS!$J$4:$S$4,O$3)/1000000 -> 7.2276787 | P14: =+SUMIFS(Client_FS!$J15:$S15,Client_FS!$J$4:$S$4,P$3)/1000000 -> 7.6615681
B15: =+Client_FS!E14 -> EBITDA Expansion 1 | G15: =+LBO!I17 -> 0 | H15: =$G$15*(SUMIFS(Client_FS!$J14:$S14,Client_FS!$J$4:$S$4,H$3)/1000000) -> 0 | I15: =$G$15*(SUMIFS(Client_FS!$J14:$S14,Client_FS!$J$4:$S$4,I$3)/1000000) -> 0 | J15: =$G$15*(SUMIFS(Client_FS!$J14:$S14,Client_FS!$J$4:$S$4,J$3)/1000000) -> 0 | K15: =$G$15*(SUMIFS(Client_FS!$J14:$S14,Client_FS!$J$4:$S$4,K$3)/1000000) -> 0 | L15: =$G$15*(SUMIFS(Client_FS!$J14:$S14,Client_FS!$J$4:$S$4,L$3)/1000000) -> 0 | M15: =$G$15*(SUMIFS(Client_FS!$J14:$S14,Client_FS!$J$4:$S$4,M$3)/1000000) -> 0 | N15: =$G$15*(SUMIFS(Client_FS!$J14:$S14,Client_FS!$J$4:$S$4,N$3)/1000000) -> 0 | O15: =$G$15*(SUMIFS(Client_FS!$J14:$S14,Client_FS!$J$4:$S$4,O$3)/1000000) -> 0 | P15: =$G$15*(SUMIFS(Client_FS!$J14:$S14,Client_FS!$J$4:$S$4,P$3)/1000000) -> 0
B16: =+Client_FS!E16 -> EBITDA Expansion 2 | G16: =+LBO!I18 -> 0 | H16: =$G$16*SUMIFS(Client_FS!$J16:$S16,Client_FS!$J$4:$S$4,H$3)/1000000 -> 0 | I16: =$G$16*SUMIFS(Client_FS!$J16:$S16,Client_FS!$J$4:$S$4,I$3)/1000000 -> 0 | J16: =$G$16*SUMIFS(Client_FS!$J16:$S16,Client_FS!$J$4:$S$4,J$3)/1000000 -> 0 | K16: =$G$16*SUMIFS(Client_FS!$J16:$S16,Client_FS!$J$4:$S$4,K$3)/1000000 -> 0 | L16: =$G$16*SUMIFS(Client_FS!$J16:$S16,Client_FS!$J$4:$S$4,L$3)/1000000 -> 0 | M16: =$G$16*SUMIFS(Client_FS!$J16:$S16,Client_FS!$J$4:$S$4,M$3)/1000000 -> 0 | N16: =$G$16*SUMIFS(Client_FS!$J16:$S16,Client_FS!$J$4:$S$4,N$3)/1000000 -> 0 | O16: =$G$16*SUMIFS(Client_FS!$J16:$S16,Client_FS!$J$4:$S$4,O$3)/1000000 -> 0 | P16: =$G$16*SUMIFS(Client_FS!$J16:$S16,Client_FS!$J$4:$S$4,P$3)/1000000 -> 0
B17: =+Client_FS!E17 -> M&A EBITDA | G17: =+LBO!I19 -> 1 | H17: =$G$17*SUMIFS(Client_FS!$J17:$S17,Client_FS!$J$4:$S$4,H$3)/1000000 -> 0 | I17: =$G$17*SUMIFS(Client_FS!$J17:$S17,Client_FS!$J$4:$S$4,I$3)/1000000 -> 0 | J17: =$G$17*SUMIFS(Client_FS!$J17:$S17,Client_FS!$J$4:$S$4,J$3)/1000000 -> 0.25 | K17: =$G$17*SUMIFS(Client_FS!$J17:$S17,Client_FS!$J$4:$S$4,K$3)/1000000 -> 1 | L17: =$G$17*SUMIFS(Client_FS!$J17:$S17,Client_FS!$J$4:$S$4,L$3)/1000000 -> 1.03 | M17: =$G$17*SUMIFS(Client_FS!$J17:$S17,Client_FS!$J$4:$S$4,M$3)/1000000 -> 1.0609 | N17: =$G$17*SUMIFS(Client_FS!$J17:$S17,Client_FS!$J$4:$S$4,N$3)/1000000 -> 1.092727 | O17: =$G$17*SUMIFS(Client_FS!$J17:$S17,Client_FS!$J$4:$S$4,O$3)/1000000 -> 1.1255088 | P17: =$G$17*SUMIFS(Client_FS!$J17:$S17,Client_FS!$J$4:$S$4,P$3)/1000000 -> 1.1592741
B18: =+Client_FS!E18 -> Staff efficiencies | G18: =+LBO!I20 -> 1 | H18: =$G$18*SUMIFS(Client_FS!$J18:$S18,Client_FS!$J$4:$S$4,H$3)/1000000 -> 0 | I18: =$G$18*SUMIFS(Client_FS!$J18:$S18,Client_FS!$J$4:$S$4,I$3)/1000000 -> 0 | J18: =$G$18*SUMIFS(Client_FS!$J18:$S18,Client_FS!$J$4:$S$4,J$3)/1000000 -> -0.01607725 | K18: =$G$18*SUMIFS(Client_FS!$J18:$S18,Client_FS!$J$4:$S$4,K$3)/1000000 -> 0.6355515 | L18: =$G$18*SUMIFS(Client_FS!$J18:$S18,Client_FS!$J$4:$S$4,L$3)/1000000 -> 0.72931004 | M18: =$G$18*SUMIFS(Client_FS!$J18:$S18,Client_FS!$J$4:$S$4,M$3)/1000000 -> 0.75118934 | N18: =$G$18*SUMIFS(Client_FS!$J18:$S18,Client_FS!$J$4:$S$4,N$3)/1000000 -> 0.77372502 | O18: =$G$18*SUMIFS(Client_FS!$J18:$S18,Client_FS!$J$4:$S$4,O$3)/1000000 -> 0.79693677 | P18: =$G$18*SUMIFS(Client_FS!$J18:$S18,Client_FS!$J$4:$S$4,P$3)/1000000 -> 0.82084488
B19: =+Client_FS!E19 -> Family costs | H19: =SUMIFS(Client_FS!$J19:$S19,Client_FS!$J$4:$S$4,H$3)/1000000 -> 0 | I19: =SUMIFS(Client_FS!$J19:$S19,Client_FS!$J$4:$S$4,I$3)/1000000 -> 0 | J19: =SUMIFS(Client_FS!$J19:$S19,Client_FS!$J$4:$S$4,J$3)/1000000 -> 0.20178328 | K19: =SUMIFS(Client_FS!$J19:$S19,Client_FS!$J$4:$S$4,K$3)/1000000 -> 0.48427988 | L19: =SUMIFS(Client_FS!$J19:$S19,Client_FS!$J$4:$S$4,L$3)/1000000 -> 0.49880828 | M19: =SUMIFS(Client_FS!$J19:$S19,Client_FS!$J$4:$S$4,M$3)/1000000 -> 0.51377252 | N19: =SUMIFS(Client_FS!$J19:$S19,Client_FS!$J$4:$S$4,N$3)/1000000 -> 0.5291857 | O19: =SUMIFS(Client_FS!$J19:$S19,Client_FS!$J$4:$S$4,O$3)/1000000 -> 0.54506127 | P19: =SUMIFS(Client_FS!$J19:$S19,Client_FS!$J$4:$S$4,P$3)/1000000 -> 0.56141311
B20: M&A EBITDA (out of plan) | G20: =+LBO!I21 -> 0 | H20: =+$G$20*0 -> 0 | I20: =+$G$20*0 -> 0 | J20: =+$G$20*0 -> 0 | K20: =+$G$20*0 -> 0 | L20: =+$G$20*0 -> 0 | M20: =+$G$20*0 -> 0 | N20: =+$G$20*0 -> 0 | O20: =+$G$20*0 -> 0 | P20: =+$G$20*0 -> 0
B21: EBITDA | H21: =SUM(H13:H20) -> 9.7002842 | I21: =SUM(I13:I20) -> 10.569617 | J21: =SUM(J13:J20) -> 11.478485 | K21: =SUM(K13:K20) -> 13.521249 | L21: =SUM(L13:L20) -> 14.229894 | M21: =SUM(M13:M20) -> 14.838003 | N21: =SUM(N13:N20) -> 15.532952 | O21: =SUM(O13:O20) -> 16.232013 | P21: =SUM(P13:P20) -> 16.936182 | Q21: =Q22*Q10 -> 17.505262
B22: EBITDA margin | H22: =IFERROR(H21/H10,"") -> 0.19090414 | I22: =IFERROR(I21/I10,"") -> 0.14159662 | J22: =IFERROR(J21/J10,"") -> 0.14710607 | K22: =IFERROR(K21/K10,"") -> 0.16722452 | L22: =IFERROR(L21/L10,"") -> 0.16998345 | M22: =IFERROR(M21/M10,"") -> 0.16942109 | N22: =IFERROR(N21/N10,"") -> 0.17146937 | O22: =IFERROR(O21/O10,"") -> 0.17323596 | P22: =IFERROR(P21/P10,"") -> 0.17487513 | Q22: =P22 -> 0.17487513
B23: EBITDA Growth | H23: =IFERROR(H21/G21-1,"") | I23: =IFERROR(I21/H21-1,"") -> 0.089619361 | J23: =IFERROR(J21/I21-1,"") -> 0.085988707 | K23: =IFERROR(K21/J21-1,"") -> 0.17796457 | L23: =IFERROR(L21/K21-1,"") -> 0.052409743 | M23: =IFERROR(M21/L21-1,"") -> 0.042734575 | N23: =IFERROR(N21/M21-1,"") -> 0.046835799 | O23: =IFERROR(O21/N21-1,"") -> 0.045005024 | ... Q23: =IFERROR(Q21/P21-1,"") -> 0.033601439
B25: Core EBIT
B26: Growth EBIT
B27: M&A EBIT
B28: EBIT | H28: =SUM(H25:H27) -> 0 | I28: =SUM(I25:I27) -> 0 | J28: =SUM(J25:J27) -> 0 | K28: =SUM(K25:K27) -> 0 | L28: =SUM(L25:L27) -> 0 | M28: =SUM(M25:M27) -> 0 | N28: =SUM(N25:N27) -> 0 | O28: =SUM(O25:O27) -> 0 | ... Q28: =SUM(Q25:Q27) -> 0
B29: Core margin | H29: =IFERROR(H25/H5,"") -> 0 | I29: =IFERROR(I25/I5,"") -> 0 | J29: =IFERROR(J25/J5,"") -> 0 | K29: =IFERROR(K25/K5,"") -> 0 | L29: =IFERROR(L25/L5,"") -> 0 | M29: =IFERROR(M25/M5,"") -> 0 | N29: =IFERROR(N25/N5,"") -> 0 | O29: =IFERROR(O25/O5,"") -> 0 | ... Q29: =IFERROR(Q25/Q5,"")
B30: EBIT margin | H30: =IFERROR(H28/H10,"") -> 0 | I30: =IFERROR(I28/I10,"") -> 0 | J30: =IFERROR(J28/J10,"") -> 0 | K30: =IFERROR(K28/K10,"") -> 0 | L30: =IFERROR(L28/L10,"") -> 0 | M30: =IFERROR(M28/M10,"") -> 0 | N30: =IFERROR(N28/N10,"") -> 0 | O30: =IFERROR(O28/O10,"") -> 0 | ... Q30: =IFERROR(Q28/Q10,"") -> 0
B32: =+Client_FS!E25 -> Depreciation Core 1 | H32: =(SUMIFS(Client_FS!$J25:$S25,Client_FS!$J$4:$S$4,H$3)/1000000) -> -0.87535688 | I32: =(SUMIFS(Client_FS!$J25:$S25,Client_FS!$J$4:$S$4,I$3)/1000000) -> -0.90209569 | J32: =(SUMIFS(Client_FS!$J25:$S25,Client_FS!$J$4:$S$4,J$3)/1000000) -> -0.83376738 | K32: =(SUMIFS(Client_FS!$J25:$S25,Client_FS!$J$4:$S$4,K$3)/1000000) -> -0.96087987 | L32: =(SUMIFS(Client_FS!$J25:$S25,Client_FS!$J$4:$S$4,L$3)/1000000) -> -1.0336077 | M32: =(SUMIFS(Client_FS!$J25:$S25,Client_FS!$J$4:$S$4,M$3)/1000000) -> -1.1169494 | N32: =(SUMIFS(Client_FS!$J25:$S25,Client_FS!$J$4:$S$4,N$3)/1000000) -> -1.1710022 | O32: =(SUMIFS(Client_FS!$J25:$S25,Client_FS!$J$4:$S$4,O$3)/1000000) -> -1.1605476 | P32: =(SUMIFS(Client_FS!$J25:$S25,Client_FS!$J$4:$S$4,P$3)/1000000) -> -1.160353
B33: =+Client_FS!E27 -> Depreciation Core 2 | H33: =(SUMIFS(Client_FS!$J27:$S27,Client_FS!$J$4:$S$4,H$3)/1000000) -> -1.6720666 | I33: =(SUMIFS(Client_FS!$J27:$S27,Client_FS!$J$4:$S$4,I$3)/1000000) -> -2.0597406 | J33: =(SUMIFS(Client_FS!$J27:$S27,Client_FS!$J$4:$S$4,J$3)/1000000) -> -2.2535716 | K33: =(SUMIFS(Client_FS!$J27:$S27,Client_FS!$J$4:$S$4,K$3)/1000000) -> -2.3127185 | L33: =(SUMIFS(Client_FS!$J27:$S27,Client_FS!$J$4:$S$4,L$3)/1000000) -> -2.325871 | M33: =(SUMIFS(Client_FS!$J27:$S27,Client_FS!$J$4:$S$4,M$3)/1000000) -> -2.415434 | N33: =(SUMIFS(Client_FS!$J27:$S27,Client_FS!$J$4:$S$4,N$3)/1000000) -> -2.4914444 | O33: =(SUMIFS(Client_FS!$J27:$S27,Client_FS!$J$4:$S$4,O$3)/1000000) -> -2.4914444 | P33: =(SUMIFS(Client_FS!$J27:$S27,Client_FS!$J$4:$S$4,P$3)/1000000) -> -1.4068164
B34: =+Client_FS!E26 -> Depreciation Expansion 1 | G34: =+LBO!I17 -> 0 | H34: =(SUMIFS(Client_FS!$J26:$S26,Client_FS!$J$4:$S$4,H$3)/1000000)*$G34 -> 0 | I34: =(SUMIFS(Client_FS!$J26:$S26,Client_FS!$J$4:$S$4,I$3)/1000000)*$G34 -> 0 | J34: =(SUMIFS(Client_FS!$J26:$S26,Client_FS!$J$4:$S$4,J$3)/1000000)*$G34 -> 0 | K34: =(SUMIFS(Client_FS!$J26:$S26,Client_FS!$J$4:$S$4,K$3)/1000000)*$G34 -> 0 | L34: =(SUMIFS(Client_FS!$J26:$S26,Client_FS!$J$4:$S$4,L$3)/1000000)*$G34 -> 0 | M34: =(SUMIFS(Client_FS!$J26:$S26,Client_FS!$J$4:$S$4,M$3)/1000000)*$G34 -> 0 | N34: =(SUMIFS(Client_FS!$J26:$S26,Client_FS!$J$4:$S$4,N$3)/1000000)*$G34 -> 0 | O34: =(SUMIFS(Client_FS!$J26:$S26,Client_FS!$J$4:$S$4,O$3)/1000000)*$G34 -> 0 | P34: =(SUMIFS(Client_FS!$J26:$S26,Client_FS!$J$4:$S$4,P$3)/1000000)*$G34 -> 0
B35: =+Client_FS!E28 -> Depreciation Expansion 2 | G35: =+LBO!I18 -> 0 | H35: =(SUMIFS(Client_FS!$J28:$S28,Client_FS!$J$4:$S$4,H$3)/1000000)*$G35 -> 0 | I35: =(SUMIFS(Client_FS!$J28:$S28,Client_FS!$J$4:$S$4,I$3)/1000000)*$G35 -> 0 | J35: =(SUMIFS(Client_FS!$J28:$S28,Client_FS!$J$4:$S$4,J$3)/1000000)*$G35 -> 0 | K35: =(SUMIFS(Client_FS!$J28:$S28,Client_FS!$J$4:$S$4,K$3)/1000000)*$G35 -> 0 | L35: =(SUMIFS(Client_FS!$J28:$S28,Client_FS!$J$4:$S$4,L$3)/1000000)*$G35 -> 0 | M35: =(SUMIFS(Client_FS!$J28:$S28,Client_FS!$J$4:$S$4,M$3)/1000000)*$G35 -> 0 | N35: =(SUMIFS(Client_FS!$J28:$S28,Client_FS!$J$4:$S$4,N$3)/1000000)*$G35 -> 0 | O35: =(SUMIFS(Client_FS!$J28:$S28,Client_FS!$J$4:$S$4,O$3)/1000000)*$G35 -> 0 | P35: =(SUMIFS(Client_FS!$J28:$S28,Client_FS!$J$4:$S$4,P$3)/1000000)*$G35 -> 0
B36: =+Client_FS!E29 -> M&A Depreciation | G36: =+LBO!I21 -> 0 | H36: =+$G$36*0 -> 0 | I36: =+$G$36*0 -> 0 | J36: =+$G$36*0 -> 0 | K36: =+$G$36*0 -> 0 | L36: =+$G$36*0 -> 0 | M36: =+$G$36*0 -> 0 | N36: =+$G$36*0 -> 0 | O36: =+$G$36*0 -> 0 | P36: =+$G$36*0 -> 0
B37: DEPRECIATION | H37: =SUM(H32:H36) -> -2.5474234 | I37: =SUM(I32:I36) -> -2.9618363 | J37: =SUM(J32:J36) -> -3.087339 | K37: =SUM(K32:K36) -> -3.2735984 | L37: =SUM(L32:L36) -> -3.3594787 | M37: =SUM(M32:M36) -> -3.5323834 | N37: =SUM(N32:N36) -> -3.6624466 | O37: =SUM(O32:O36) -> -3.651992 | P37: =SUM(P32:P36) -> -2.5671694 | Q37: =+Q38*Q10 -> -3.6741861
B38: Core - % of revenue | H38: =IFERROR((H32+H33)/H5,"") -> -0.079716808 | I38: =IFERROR((I32+I33)/I5,"") -> -0.054347451 | J38: =IFERROR((J32+J33)/J5,"") -> -0.054121255 | K38: =IFERROR((K32+K33)/K5,"") -> -0.05545302 | L38: =IFERROR((L32+L33)/L5,"") -> -0.055057756 | M38: =IFERROR((M32+M33)/M5,"") -> -0.055608124 | N38: =IFERROR((N32+N33)/N5,"") -> -0.055816949 | O38: =IFERROR((O32+O33)/O5,"") -> -0.053881739 | P38: =IFERROR((P32+P33)/P5,"") -> -0.036704609 | Q38: =P38 -> -0.036704609
B40: =+Client_FS!E38 -> Maintenance Capex Core 1 | H40: =(SUMIFS(Client_FS!$J38:$S38,Client_FS!$J$4:$S$4,H$3))/1000000 -> -0.90796659 | I40: =(SUMIFS(Client_FS!$J38:$S38,Client_FS!$J$4:$S$4,I$3))/1000000 -> 0.19551528 | J40: =(SUMIFS(Client_FS!$J38:$S38,Client_FS!$J$4:$S$4,J$3))/1000000 -> -1.0145 | K40: =(SUMIFS(Client_FS!$J38:$S38,Client_FS!$J$4:$S$4,K$3))/1000000 -> -1 | L40: =(SUMIFS(Client_FS!$J38:$S38,Client_FS!$J$4:$S$4,L$3))/1000000 -> -1 | M40: =(SUMIFS(Client_FS!$J38:$S38,Client_FS!$J$4:$S$4,M$3))/1000000 -> -1 | N40: =(SUMIFS(Client_FS!$J38:$S38,Client_FS!$J$4:$S$4,N$3))/1000000 -> -1 | O40: =(SUMIFS(Client_FS!$J38:$S38,Client_FS!$J$4:$S$4,O$3))/1000000 -> -1 | P40: =(SUMIFS(Client_FS!$J38:$S38,Client_FS!$J$4:$S$4,P$3))/1000000 -> -1 | Q40: =Q5*Q46 -> 0
B41: =+Client_FS!E40 -> Maintenance Capex Core 2 | H41: =(SUMIFS(Client_FS!$J40:$S40,Client_FS!$J$4:$S$4,H$3))/1000000 -> -2.0044979 | I41: =(SUMIFS(Client_FS!$J40:$S40,Client_FS!$J$4:$S$4,I$3))/1000000 -> -3.4097529 | J41: =(SUMIFS(Client_FS!$J40:$S40,Client_FS!$J$4:$S$4,J$3))/1000000 -> -0.45 | K41: =(SUMIFS(Client_FS!$J40:$S40,Client_FS!$J$4:$S$4,K$3))/1000000 -> -1 | L41: =(SUMIFS(Client_FS!$J40:$S40,Client_FS!$J$4:$S$4,L$3))/1000000 -> -1 | M41: =(SUMIFS(Client_FS!$J40:$S40,Client_FS!$J$4:$S$4,M$3))/1000000 -> -1 | N41: =(SUMIFS(Client_FS!$J40:$S40,Client_FS!$J$4:$S$4,N$3))/1000000 -> -1 | O41: =(SUMIFS(Client_FS!$J40:$S40,Client_FS!$J$4:$S$4,O$3))/1000000 -> -1 | P41: =(SUMIFS(Client_FS!$J40:$S40,Client_FS!$J$4:$S$4,P$3))/1000000 -> -1 | Q41: =(SUMIFS(Client_FS!$J40:$S40,Client_FS!$J$4:$S$4,Q$3)+SUMIFS(Client_FS!$J41:$S41,Client_FS!$J$4:$S$4,Q$3))/1000000 -> 0
B42: =+Client_FS!E39 -> Growth Capex Expansion 1 | G42: =+LBO!I17 -> 0 | H42: =(SUMIFS(Client_FS!$J39:$S39,Client_FS!$J$4:$S$4,H$3)/1000000)*$G42 -> 0 | I42: =(SUMIFS(Client_FS!$J39:$S39,Client_FS!$J$4:$S$4,I$3)/1000000)*$G42 -> 0 | J42: =(SUMIFS(Client_FS!$J39:$S39,Client_FS!$J$4:$S$4,J$3)/1000000)*$G42 -> 0 | K42: =(SUMIFS(Client_FS!$J39:$S39,Client_FS!$J$4:$S$4,K$3)/1000000)*$G42 -> 0 | L42: =(SUMIFS(Client_FS!$J39:$S39,Client_FS!$J$4:$S$4,L$3)/1000000)*$G42 -> 0 | M42: =(SUMIFS(Client_FS!$J39:$S39,Client_FS!$J$4:$S$4,M$3)/1000000)*$G42 -> 0 | N42: =(SUMIFS(Client_FS!$J39:$S39,Client_FS!$J$4:$S$4,N$3)/1000000)*$G42 -> 0 | O42: =(SUMIFS(Client_FS!$J39:$S39,Client_FS!$J$4:$S$4,O$3)/1000000)*$G42 -> 0 | P42: =(SUMIFS(Client_FS!$J39:$S39,Client_FS!$J$4:$S$4,P$3)/1000000)*$G42 -> 0
B43: =+Client_FS!E41 -> Growth Capex Expansion 2 | G43: =+LBO!I18 -> 0 | H43: =(SUMIFS(Client_FS!$J41:$S41,Client_FS!$J$4:$S$4,H$3)/1000000)*$G43 -> 0 | I43: =(SUMIFS(Client_FS!$J41:$S41,Client_FS!$J$4:$S$4,I$3)/1000000)*$G43 -> 0 | J43: =(SUMIFS(Client_FS!$J41:$S41,Client_FS!$J$4:$S$4,J$3)/1000000)*$G43 -> 0 | K43: =(SUMIFS(Client_FS!$J41:$S41,Client_FS!$J$4:$S$4,K$3)/1000000)*$G43 -> 0 | L43: =(SUMIFS(Client_FS!$J41:$S41,Client_FS!$J$4:$S$4,L$3)/1000000)*$G43 -> 0 | M43: =(SUMIFS(Client_FS!$J41:$S41,Client_FS!$J$4:$S$4,M$3)/1000000)*$G43 -> 0 | N43: =(SUMIFS(Client_FS!$J41:$S41,Client_FS!$J$4:$S$4,N$3)/1000000)*$G43 -> 0 | O43: =(SUMIFS(Client_FS!$J41:$S41,Client_FS!$J$4:$S$4,O$3)/1000000)*$G43 -> 0 | P43: =(SUMIFS(Client_FS!$J41:$S41,Client_FS!$J$4:$S$4,P$3)/1000000)*$G43 -> 0
B44: =+Client_FS!E42 -> M&A Capex | G44: =+LBO!I21 -> 0 | H44: =(SUMIFS(Client_FS!$J42:$S42,Client_FS!$J$4:$S$4,H$3)/1000000)*$G44 -> 0 | I44: =(SUMIFS(Client_FS!$J42:$S42,Client_FS!$J$4:$S$4,I$3)/1000000)*$G44 -> 0 | J44: =(SUMIFS(Client_FS!$J42:$S42,Client_FS!$J$4:$S$4,J$3)/1000000)*$G44 -> 0 | K44: =(SUMIFS(Client_FS!$J42:$S42,Client_FS!$J$4:$S$4,K$3)/1000000)*$G44 -> 0 | L44: =(SUMIFS(Client_FS!$J42:$S42,Client_FS!$J$4:$S$4,L$3)/1000000)*$G44 -> 0 | M44: =(SUMIFS(Client_FS!$J42:$S42,Client_FS!$J$4:$S$4,M$3)/1000000)*$G44 -> 0 | N44: =(SUMIFS(Client_FS!$J42:$S42,Client_FS!$J$4:$S$4,N$3)/1000000)*$G44 -> 0 | O44: =(SUMIFS(Client_FS!$J42:$S42,Client_FS!$J$4:$S$4,O$3)/1000000)*$G44 -> 0 | P44: =(SUMIFS(Client_FS!$J42:$S42,Client_FS!$J$4:$S$4,P$3)/1000000)*$G44 -> 0
B45: CAPEX | H45: =SUM(H40:H44) -> -2.9124645 | I45: =SUM(I40:I44) -> -3.2142376 | J45: =SUM(J40:J44) -> -1.4645 | K45: =SUM(K40:K44) -> -2 | L45: =SUM(L40:L44) -> -2 | M45: =SUM(M40:M44) -> -2 | N45: =SUM(N40:N44) -> -2 | O45: =SUM(O40:O44) -> -2 | P45: =SUM(P40:P44) -> -2 | Q45: =SUM(Q40:Q43) -> 0
...

Sheet LBO
A2: Basics
B4: Year | I4: =YEAR(I5) -> 2024 | J4: =YEAR(J5) -> 2025 | K4: =YEAR(K5) -> 2026 | L4: =YEAR(L5) -> 2027 | M4: =YEAR(M5) -> 2028 | N4: =YEAR(N5) -> 2029 | O4: =YEAR(O5) -> 2030 | P4: =YEAR(P5) -> 2031 | Q4: =YEAR(Q5) -> 2032
B5: Year end date | I5: 45657 | J5: =EDATE(I5,12) -> 46022 | K5: =EDATE(J5,12) -> 46387 | L5: =EDATE(K5,12) -> 46752 | M5: =EDATE(L5,12) -> 47118 | N5: =EDATE(M5,12) -> 47483 | O5: =EDATE(N5,12) -> 47848 | P5: =EDATE(O5,12) -> 48213 | Q5: =EDATE(P5,12) -> 48579
B6: Type | I6: Actual | J6: Actual | K6: Outlook | L6: Forecast | M6: Forecast | N6: Forecast | O6: Forecast | P6: Forecast | Q6: Forecast
B8: Project Name | I8: [x]
B9: Scenario | I9: Management | L9: Management
B10: Currency | I10: GBP | L10: Base
B11: First fiscal YE following acquisition | I11: 46387 | J11: =I11>I28 -> TRUE | L11: Downside
B12: (Effective) Tax rate | I12: 0.25
A14: Acquisition assumptions
B16: Scenario selection | J16: Scenario | O16: Structuring EBITDA
C17: Switch 1 | G17: switch | I17: 0 | O17: EBITDA per mgmt
C18: Switch 2 | G18: switch | I18: 0 | O18: Less:
C19: Switch 3 | G19: switch | I19: 1 | O19: Add:
C20: Staff efficiencies | G20: switch | I20: 1 | O20: Add:
C21: M&A | G21: switch | I21: 0 | O21: Add:
I22: 0 | O22: Add:
I23: 1 | O23: Add:
J24: Sensitivity range | O24: Structuring EBITDA | R24: =SUM(R17:R23) -> 0
B25: Acquisition multiple | G25: =H26&" basis" -> Adj basis | I25: 10 | J25: 0.5 | L25: LFY | M25: =INDEX($I$132:$Q$132,MATCH(EDATE(I11,-12),$I$127:$Q$127,0)) -> 10.569617
B26: Acquisition EBITDA | H26: Adj | I26: =INDEX(M25:M28,MATCH(H26,L25:L28,0)) -> 13.5 | L26: LTM | M26: =INDEX($I$132:$Q$132,MATCH(EDATE(I11,-12),$I$127:$Q$127,))*(1-stub)+G132 -> 11.024051
B27: Exit multiple | G27: LTM EBITDA | I27: =+I25 -> 10 | J27: 0.5 | L27: NTM | M27: =INDEX($I$132:$Q$132,MATCH(I11,$I$127:$Q$127,0))*(1-stub)+G132 -> 11.478485
B28: Acquisition date | G28: date | I28: 46203 | L28: Adj | M28: 13.5
B29: Stub period | G29: %age | I29: =+MROUND((I11-I28)/365.25,1/12) -> 0.5
B30: Holding period | G30: yrs | I30: 5
B31: Exit date | G31: date | I31: =EDATE(I28,(12*I30)) -> 48029
B32: M&A acquisition transaction fees | G32: £m | I32: 2
B33: Financing transaction fees | G33: £m | I33: =+SUM(J46*I54,J47*I55) -> 0.90845862
B34: Annual fee amortization | G34: £m | I34: =SUM(I32:I33)/I30 -> 0.58169172
A36: Financing & cap table assumptions
J37: Sensitivity range
B38: Total debt / EBITDA | G38: EBITDA multiple | I38: 5.73 | J38: 0.5
B39: Financing EBITDA | G39: date | H39: =EDATE(I11,-12) -> 46022 | I39: =INDEX($I$132:$Q$132,MATCH($H$39,$I$127:$Q$127,0)) -> 10.569617
B40: Minimum equity | G40: % | I40: 0.35
A41: =SUM(H65:I65,O45:O47,J53,J41)=0 -> TRUE | B41: 3M SONIA @ entry | I41: =+AVERAGEIFS(GBPSONIA!$C$10:$C$130,GBPSONIA!$B$10:$B$130,">="&$I$28,GBPSONIA!$B$10:$B$130,"<"&I11) -> 0.040617783 | J41: =I41=$K$220 -> TRUE
H43: Spread | I43: Base | J43: Fee | K43: Fixed? | L43: Cash interest | M43: Yrly principal | N43: Optional paydown
B44: Cash | G44: % | H44: 0 | I44: 0 | K44: 1
B45: RCF | G45: % | H45: 0.05 | I45: =$I$41 -> 0.040617783 | J45: 0 | K45: 0 | L45: 1 | N45: 1 | O45: =I45=$K$220 -> TRUE
B46: TL A (rate) | G46: % | H46: 0.05 | I46: =$I$41 -> 0.040617783 | J46: 0.015 | K46: 0 | L46: 1 | M46: 0 | N46: 0 | O46: =I46=$K$220 -> TRUE
B47: TL B (rate) | G47: % | H47: 0.05 | I47: =$I$41 -> 0.040617783 | J47: 0 | K47: 0 | L47: 1 | M47: 0 | N47: 0 | O47: =I47=$K$220 -> TRUE
...

Sheet 1PageOutput
A1: Transaction overview
B4: Total funding requirements | D4: Financing structure | F4: Illustrative shareholder structure @ acquisition | H4: Equity Value at exit
B5: (including fees)
B6: =+LBO!I83 -> 137.90846 | D6: =+LBO!G96 -> 137.90846 | H6: =+LBO!M188 -> 126.77987
H11: Founders / mgt
H12: IRR :n/a
H13: MM: n/a
H14: ="Value: "&TEXT(LBO!M200,"£#,##0.0")&"m" -> Value: £0.5m
H16: Financial sponsor
H17: ="IRR: "&TEXT(LBO!M212,"0%") -> IRR: 10%
H18: ="MOIC: "&TEXT(LBO!M213,"0.0x") -> MOIC: 1.6x
H19: ="Value: "&TEXT(SUM(LBO!M204:M210),"£#,##0.0")&"m" -> Value: £126.3m
D24: Entry Enterprise Value | H24: Exit Enterprise Value
D25: =+TEV -> #NAME? | H25: =+LBO!M186 -> 158.82483
D26: =TEXT(_xlfn.SINGLE(Acq_multiple),"0.0x")&" EBITDA" -> 10.0x EBITDA | H26: =TEXT(Exit_multiple,"0.0x")&" EBITDA" -> 10.0x EBITDA
B30: Uses
B31: Equity consideration | C31: =+LBO!I80 -> 135
B32: =IF(C32=0,"","Repay outstanding debt") | C32: =+LBO!I81 -> 0
B33: Transaction fees | C33: =+LBO!I82 -> 2.9084586
B35: Sources
B36: New Equity | C36: =+LBO!O72 -> 77.228534
B37: =IF(C37=0,"","Existing cash") | C37: =+LBO!G89 -> 0
B38: =IF(C38=0,"","Management strip") | C38: =+LBO!O73 -> 0
B39: External debt | C39: =+LBO!G92 -> 60.563908
B41: =IF(C41=0,"","Founders/management") -> Founders/management | C41: =+SUM(LBO!O73:O74)/LBO!O75 -> 0.0015
B42: Financial sponsor | C42: =+LBO!O72/LBO!O75 -> 0.9985

Sheet GBPSONIA
B2: 3-month SONIA Compounded Forward Curve
R3: Get the latest curve at:
B4: As of: | C4: 46126 | R4: https://chathamdirect.com/rates/market-rates/europe/sonia/forward-curves
L5: Chatham Financial - Proprietary and Confidential - All Rights Reserved
B9: Date | C9: 3 Month Compounded
B10: 46128 | C10: 0.0379325
B11: 46160 | C11: 0.0385398
B12: 46189 | C12: 0.0392038
B13: 46219 | C13: 0.0397772
B14: 46251 | C14: 0.0402593
B15: 46281 | C15: 0.0406242
B16: 46311 | C16: 0.0409066
B17: 46342 | C17: 0.0410505
B18: 46372 | C18: 0.0410889
B19: 46405 | C19: 0.0410482
B20: 46434 | C20: 0.0409542
B21: 46462 | C21: 0.040833
... B130: 49781 | C130: 0.0497763
